c++ threads/scripts/2thread_test.in
2
o
0 S 203 META 137 7
0 C 203
0 w 203
1 B 204 AMZN 470 2
1 C 204
1 w 204
0 S 205 AMZN 460 4
0 C 205
0 w 205
1 B 206 MSFT 452 4
1 C 206
1 w 206
0 B 207 MSFT 446 8
0 C 207
0 w 207
1 S 208 GOOG 224 8
1 C 208
1 w 208
0 S 209 GOOG 281 3
0 C 209
0 w 209
1 S 210 GOOG 388 9
1 C 210
1 w 210
0 S 211 META 441 5
0 C 211
0 w 211
1 S 212 AMZN 497 9
1 C 212
1 w 212
x
