c++ threads/scripts/4thread_test.in
4
o
0 S 201 META 100 5
1 S 202 META 100 5
2 S 203 META 100 5
3 S 204 META 100 5
0 w 201
1 w 202
2 w 203
3 w 204
0 S 209 META 100 5
1 S 210 META 100 5
2 S 211 META 100 5
3 S 212 META 100 5
0 w 209
1 w 210
2 w 211
3 w 212
0 S 217 META 100 5
1 S 218 META 100 5
2 S 219 META 100 5
3 S 220 META 100 5
0 w 217
1 w 218
2 w 219
3 w 220
0 S 225 META 100 5
1 S 226 META 100 5
2 S 227 META 100 5
3 S 228 META 100 5
0 w 225
1 w 226
2 w 227
3 w 228
0 S 233 META 100 5
1 S 234 META 100 5
2 S 235 META 100 5
3 S 236 META 100 5
0 w 233
1 w 234
2 w 235
3 w 236
0 S 241 META 100 5
1 S 242 META 100 5
2 S 243 META 100 5
3 S 244 META 100 5
0 B 245 APPL 200 10
1 B 246 APPL 200 10
2 B 247 APPL 200 10
3 B 248 APPL 200 10
0 w 241
1 w 242
2 w 243
3 w 244
x
