c++ threads/scripts/8thread_test.in
8
o
0 B 0 META 99 1
1 B 1 META 99 1
2 B 2 META 99 1
3 B 3 META 99 1
4 B 4 META 99 1
5 B 5 META 99 1
6 B 6 META 99 1
7 B 7 META 99 1
0 B 8 META 99 1
1 B 9 META 99 1
2 B 10 META 99 1
3 B 11 META 99 1
4 B 12 META 99 1
5 B 13 META 99 1
6 B 14 META 99 1
7 B 15 META 99 1
0 B 16 META 99 1
1 B 17 META 99 1
2 B 18 META 99 1
3 B 19 META 99 1
4 B 20 META 99 1
5 B 21 META 99 1
6 B 22 META 99 1
7 B 23 META 99 1
0 B 24 META 99 1
1 B 25 META 99 1
2 B 26 META 99 1
3 B 27 META 99 1
4 B 28 META 99 1
5 B 29 META 99 1
6 B 30 META 99 1
7 B 31 META 99 1
0 B 32 META 99 1
1 B 33 META 99 1
2 B 34 META 99 1
3 B 35 META 99 1
4 B 36 META 99 1
5 B 37 META 99 1
6 B 38 META 99 1
7 B 39 META 99 1
0 B 40 META 99 1
1 B 41 META 99 1
2 B 42 META 99 1
3 B 43 META 99 1
4 B 44 META 99 1
5 B 45 META 99 1
6 B 46 META 99 1
7 B 47 META 99 1
0 B 48 META 99 1
1 B 49 META 99 1
2 B 50 META 99 1
3 B 51 META 99 1
4 B 52 META 99 1
5 B 53 META 99 1
6 B 54 META 99 1
7 B 55 META 99 1
x
